Workbook

Sheet stock
A1: sku (не менять) | B1: фото | C1: товар | D1: размер | E1: цвет | F1: остаток | G1: категория | H1: цена, ₽
A2: women-socks-bowknot-35-40-cream | B2: =IMAGE("https://nosinoski.ru/products/women-socks-bowknot/1792100000014.jpg") | C2: Женские носки «Bowknot» с рюшей | D2: 35-40 | E2: Молочные | F2: 5 | G2: Женские носки | H2: 220
A3: women-socks-bowknot-35-40-navy | B3: =IMAGE("https://nosinoski.ru/products/women-socks-bowknot/1792100000014.jpg") | C3: Женские носки «Bowknot» с рюшей | D3: 35-40 | E3: Тёмно-синие | F3: 5 | G3: Женские носки | H3: 220
A4: women-socks-bowknot-35-40-black | B4: =IMAGE("https://nosinoski.ru/products/women-socks-bowknot/1792100000014.jpg") | C4: Женские носки «Bowknot» с рюшей | D4: 35-40 | E4: Чёрные | F4: 5 | G4: Женские носки | H4: 220
A5: women-socks-flowers-35-40-beige | B5: =IMAGE("https://nosinoski.ru/products/women-socks-flowers/1792100000011.jpg") | C5: Женские носки «Цветочки», мягкая резинка | D5: 35-40 | E5: Бежевые | F5: 5 | G5: Женские носки | H5: 220
A6: women-socks-flowers-35-40-lilac | B6: =IMAGE("https://nosinoski.ru/products/women-socks-flowers/1792100000011.jpg") | C6: Женские носки «Цветочки», мягкая резинка | D6: 35-40 | E6: Сиреневые | F6: 5 | G6: Женские носки | H6: 220
A7: women-socks-flowers-35-40-grey | B7: =IMAGE("https://nosinoski.ru/products/women-socks-flowers/1792100000011.jpg") | C7: Женские носки «Цветочки», мягкая резинка | D7: 35-40 | E7: Тёмно-серые | F7: 5 | G7: Женские носки | H7: 220
A8: women-socks-ruffle-stripes-35-40-white | B8: =IMAGE("https://nosinoski.ru/products/women-socks-ruffle-stripes/1792100000017.jpg") | C8: Женские носки с рюшей и полосками | D8: 35-40 | E8: Белые, чёрные полоски | F8: 5 | G8: Женские носки | H8: 220
A9: women-socks-ruffle-stripes-35-40-grey | B9: =IMAGE("https://nosinoski.ru/products/women-socks-ruffle-stripes/1792100000017.jpg") | C9: Женские носки с рюшей и полосками | D9: 35-40 | E9: Серые, белые полоски | F9: 5 | G9: Женские носки | H9: 220
A10: women-socks-glam-35-40-white | B10: =IMAGE("https://nosinoski.ru/products/women-socks-glam/1792100000020.jpg") | C10: Носки Glam Socks, белые | D10: 35-40 | E10: Белые | F10: 5 | G10: Женские носки | H10: 200
A11: women-socks-glam-35-40-whitegrey | B11: =IMAGE("https://nosinoski.ru/products/women-socks-glam/1792100000020.jpg") | C11: Носки Glam Socks, белые | D11: 35-40 | E11: Белые с серой вставкой | F11: 5 | G11: Женские носки | H11: 200
A12: socks-bows-35-40-blue | B12: =IMAGE("https://nosinoski.ru/products/socks-bows/1792040197931.jpg") | C12: Носки «Бантики» | D12: 35-40 | E12: Голубой (оранжевый бант) | F12: 5 | G12: Женские носки | H12: 250
A13: socks-bows-35-40-cream | B13: =IMAGE("https://nosinoski.ru/products/socks-bows/1792040197931.jpg") | C13: Носки «Бантики» | D13: 35-40 | E13: Кремовый (розовый бант) | F13: 5 | G13: Женские носки | H13: 250
A14: socks-bows-35-40-black | B14: =IMAGE("https://nosinoski.ru/products/socks-bows/1792040197931.jpg") | C14: Носки «Бантики» | D14: 35-40 | E14: Чёрный (красный бант) | F14: 5 | G14: Женские носки | H14: 250
A15: socks-leopard-letter-35-40-ivory | B15: =IMAGE("https://nosinoski.ru/products/socks-leopard-letter/1791995509498.jpg") | C15: Носки «Леопардовая буква» | D15: 35-40 | E15: Молочный (буква C) | F15: 5 | G15: Женские носки | H15: 250
A16: socks-leopard-letter-35-40-gray | B16: =IMAGE("https://nosinoski.ru/products/socks-leopard-letter/1791995509498.jpg") | C16: Носки «Леопардовая буква» | D16: 35-40 | E16: Серый меланж (буква P) | F16: 5 | G16: Женские носки | H16: 250
A17: socks-mini-bows-35-40-white | B17: =IMAGE("https://nosinoski.ru/products/socks-mini-bows/1792040198002.jpg") | C17: Носки «Мини-бантики» с рюшей | D17: 35-40 | E17: Белый с тёмно-синими бантиками | F17: 5 | G17: Женские носки | H17: 250
A18: socks-teddy-1986-35-40-white | B18: =IMAGE("https://nosinoski.ru/products/socks-teddy-1986/1791995509457.jpg") | C18: Носки «Мишка Teddy 1986» | D18: 35-40 | E18: Белый | F18: 5 | G18: Женские носки | H18: 250
A19: socks-teddy-1986-35-40-navy | B19: =IMAGE("https://nosinoski.ru/products/socks-teddy-1986/1791995509457.jpg") | C19: Носки «Мишка Teddy 1986» | D19: 35-40 | E19: Тёмно-синий | F19: 5 | G19: Женские носки | H19: 250
A20: socks-teddy-1986-35-40-black | B20: =IMAGE("https://nosinoski.ru/products/socks-teddy-1986/1791995509457.jpg") | C20: Носки «Мишка Teddy 1986» | D20: 35-40 | E20: Чёрный | F20: 5 | G20: Женские носки | H20: 250
A21: socks-fluffy-smile-35-40-red | B21: =IMAGE("https://nosinoski.ru/products/socks-fluffy-smile/1792040198058.jpg") | C21: Носки «Плюшевый смайл» | D21: 35-40 | E21: Бордовый | F21: 5 | G21: Женские носки | H21: 250
A22: socks-fluffy-smile-35-40-cream | B22: =IMAGE("https://nosinoski.ru/products/socks-fluffy-smile/1792040198058.jpg") | C22: Носки «Плюшевый смайл» | D22: 35-40 | E22: Молочный | F22: 5 | G22: Женские носки | H22: 250
A23: socks-fluffy-smile-35-40-gray | B23: =IMAGE("https://nosinoski.ru/products/socks-fluffy-smile/1792040198058.jpg") | C23: Носки «Плюшевый смайл» | D23: 35-40 | E23: Серый | F23: 5 | G23: Женские носки | H23: 250
A24: socks-fluffy-smile-35-40-black | B24: =IMAGE("https://nosinoski.ru/products/socks-fluffy-smile/1792040198058.jpg") | C24: Носки «Плюшевый смайл» | D24: 35-40 | E24: Чёрный | F24: 5 | G24: Женские носки | H24: 250
A25: socks-roses-35-40-cream | B25: =IMAGE("https://nosinoski.ru/products/socks-roses/1792040198036.jpg") | C25: Носки «Розы» | D25: 35-40 | E25: Молочный с чёрными розами | F25: 5 | G25: Женские носки | H25: 250
A26: socks-roses-35-40-black | B26: =IMAGE("https://nosinoski.ru/products/socks-roses/1792040198036.jpg") | C26: Носки «Розы» | D26: 35-40 | E26: Чёрный с белыми розами | F26: 5 | G26: Женские носки | H26: 250
A27: socks-smile-upside-35-40-white | B27: =IMAGE("https://nosinoski.ru/products/socks-smile-upside/1792040948963.jpg") | C27: Носки «Смайлик-класс» | D27: 35-40 | E27: Белый | F27: 5 | G27: Женские носки | H27: 250
A28: socks-smile-upside-35-40-gray | B28: =IMAGE("https://nosinoski.ru/products/socks-smile-upside/1792040948963.jpg") | C28: Носки «Смайлик-класс» | D28: 35-40 | E28: Серый | F28: 5 | G28: Женские носки | H28: 250
A29: socks-smile-upside-35-40-black | B29: =IMAGE("https://nosinoski.ru/products/socks-smile-upside/1792040948963.jpg") | C29: Носки «Смайлик-класс» | D29: 35-40 | E29: Чёрный | F29: 5 | G29: Женские носки | H29: 250
A30: men-socks-slazenger-short-40-45-grey | B30: =IMAGE("https://nosinoski.ru/products/men-socks-slazenger-short/1792100000063.jpg") | C30: Мужские короткие носки Slazenger | D30: 40-45 | E30: Серые | F30: 5 | G30: Мужские носки | H30: 200
A31: men-socks-slazenger-short-40-45-black | B31: =IMAGE("https://nosinoski.ru/products/men-socks-slazenger-short/1792100000063.jpg") | C31: Мужские короткие носки Slazenger | D31: 40-45 | E31: Чёрные | F31: 5 | G31: Мужские носки | H31: 200
A32: men-socks-stripe-40-45-tricolor | B32: =IMAGE("https://nosinoski.ru/products/men-socks-stripe/1792040432061.jpg") | C32: Мужские короткие носки «Полоска», Корея | D32: 40-45 | E32: Серые, полоска красно-бело-синяя | F32: 5 | G32: Мужские носки | H32: 220
A33: men-socks-stripe-40-45-blackblue | B33: =IMAGE("https://nosinoski.ru/products/men-socks-stripe/1792040432061.jpg") | C33: Мужские короткие носки «Полоска», Корея | D33: 40-45 | E33: Серые, полоска чёрно-бело-синяя | F33: 5 | G33: Мужские носки | H33: 220
A34: men-socks-short-stripes-40-45-greygreen | B34: =IMAGE("https://nosinoski.ru/products/men-socks-short-stripes/1792100000060.jpg") | C34: Мужские короткие носки «Полоски» | D34: 40-45 | E34: Серые, зелёная полоска | F34: 5 | G34: Мужские носки | H34: 220
A35: men-socks-short-stripes-40-45-greyred | B35: =IMAGE("https://nosinoski.ru/products/men-socks-short-stripes/1792100000060.jpg") | C35: Мужские короткие носки «Полоски» | D35: 40-45 | E35: Серые, красная полоска | F35: 5 | G35: Мужские носки | H35: 220
A36: men-socks-short-stripes-40-45-greyblue | B36: =IMAGE("https://nosinoski.ru/products/men-socks-short-stripes/1792100000060.jpg") | C36: Мужские короткие носки «Полоски» | D36: 40-45 | E36: Серые, синяя полоска | F36: 5 | G36: Мужские носки | H36: 220
A37: men-socks-short-stripes-40-45-black | B37: =IMAGE("https://nosinoski.ru/products/men-socks-short-stripes/1792100000060.jpg") | C37: Мужские короткие носки «Полоски» | D37: 40-45 | E37: Чёрные, белые полоски | F37: 5 | G37: Мужские носки | H37: 220
A38: men-socks-smile-40-45-white | B38: =IMAGE("https://nosinoski.ru/products/men-socks-smile/1792100000031.jpg") | C38: Мужские носки «Smile!» | D38: 40-45 | E38: Белые | F38: 5 | G38: Мужские носки | H38: 220
A39: men-socks-smile-40-45-grey | B39: =IMAGE("https://nosinoski.ru/products/men-socks-smile/1792100000031.jpg") | C39: Мужские носки «Smile!» | D39: 40-45 | E39: Серые | F39: 5 | G39: Мужские носки | H39: 220
A40: men-socks-smile-40-45-black | B40: =IMAGE("https://nosinoski.ru/products/men-socks-smile/1792100000031.jpg") | C40: Мужские носки «Smile!» | D40: 40-45 | E40: Чёрные | F40: 5 | G40: Мужские носки | H40: 220
...

Sheet Итого
A1: Показатель | B1: Значение
A2: Всего позиций (модель × цвет × размер) | B2: =COUNTA(stock!A2:A124)
A3: Всего штук на складе | B3: =SUM(stock!F2:F124)
A4: Закончились (0) | B4: =COUNTIF(stock!F2:F124,0)
A5: Заканчиваются (1–2) | B5: =COUNTIFS(stock!F2:F124,">=1",stock!F2:F124,"<=2")
A6: Товар на сумму, ₽ | B6: =SUMPRODUCT(stock!F2:F124,stock!H2:H124)
A8: Штук по категориям
A9: 5 | B9: =SUMIF(stock!G2:G124,"5",stock!F2:F124)

Sheet Как пользоваться
A1: Склад «Носи носки» — как пользоваться
A3: Меняйте только колонку «остаток» на листе stock. Фото подтягивается с сайта само.
A4: Пришла партия — прибавьте к числу. Продали на Авито или вживую — уменьшите.
A5: Продажи с сайта (когда подключим) спишутся сами и попадут на лист log.
A6: Красный — закончилось, жёлтый — осталось 1–2 шт.
A7: Чтобы найти модель: значок фильтра в заголовке «товар» → выбрать модель.
A8: Колонку sku не меняйте: по ней сайт узнаёт позицию.
A9: Лист «Итого» считает сам: сколько всего пар, что закончилось, сумма товара.
